[2023-07-31T12:11:18.451-0700] {taskinstance.py:1103} INFO - Dependencies all met for dep_context=non-requeueable deps ti=<TaskInstance: testdag.task3_sql manual__2023-07-31T19:11:11.075960+00:00 [queued]>
[2023-07-31T12:11:18.453-0700] {taskinstance.py:1103} INFO - Dependencies all met for dep_context=requeueable deps ti=<TaskInstance: testdag.task3_sql manual__2023-07-31T19:11:11.075960+00:00 [queued]>
[2023-07-31T12:11:18.453-0700] {taskinstance.py:1308} INFO - Starting attempt 1 of 2
[2023-07-31T12:11:18.458-0700] {taskinstance.py:1327} INFO - Executing <Task(SQLExecuteQueryOperator): task3_sql> on 2023-07-31 19:11:11.075960+00:00
[2023-07-31T12:11:18.459-0700] {standard_task_runner.py:57} INFO - Started process 63120 to run task
[2023-07-31T12:11:18.462-0700] {standard_task_runner.py:84} INFO - Running: ['airflow', 'tasks', 'run', 'testdag', 'task3_sql', 'manual__2023-07-31T19:11:11.075960+00:00', '--job-id', '25', '--raw', '--subdir', 'DAGS_FOLDER/testdag.py', '--cfg-path', '/var/folders/wq/wb1f6jvn7hs9kt8fvl1pjjf80000gn/T/tmpugit7bue']
[2023-07-31T12:11:18.462-0700] {standard_task_runner.py:85} INFO - Job 25: Subtask task3_sql
[2023-07-31T12:11:18.476-0700] {task_command.py:410} INFO - Running <TaskInstance: testdag.task3_sql manual__2023-07-31T19:11:11.075960+00:00 [running]> on host sriharshas-macbook-pro.local
[2023-07-31T12:11:18.498-0700] {taskinstance.py:1545} INFO - Exporting env vars: AIRFLOW_CTX_DAG_OWNER='airflow' AIRFLOW_CTX_DAG_ID='testdag' AIRFLOW_CTX_TASK_ID='task3_sql' AIRFLOW_CTX_EXECUTION_DATE='2023-07-31T19:11:11.075960+00:00' AIRFLOW_CTX_TRY_NUMBER='1' AIRFLOW_CTX_DAG_RUN_ID='manual__2023-07-31T19:11:11.075960+00:00'
[2023-07-31T12:11:18.499-0700] {sql.py:265} INFO - Executing: SELECT 1; SELECT * FROM public.product LIMIT 1;
[2023-07-31T12:11:18.501-0700] {base.py:73} INFO - Using connection ID '***_default' for task execution.
[2023-07-31T12:11:18.510-0700] {taskinstance.py:1824} ERROR - Task failed with exception
Traceback (most recent call last):
  File "/Users/sriharshabasiri/Library/Python/3.9/lib/python/site-packages/airflow/providers/common/sql/operators/sql.py", line 266, in execute
    hook = self.get_db_hook()
  File "/Users/sriharshabasiri/Library/Python/3.9/lib/python/site-packages/airflow/providers/common/sql/operators/sql.py", line 181, in get_db_hook
    return self._hook
  File "/Library/Developer/CommandLineTools/Library/Frameworks/Python3.framework/Versions/3.9/lib/python3.9/functools.py", line 969, in __get__
    val = self.func(instance)
  File "/Users/sriharshabasiri/Library/Python/3.9/lib/python/site-packages/airflow/providers/common/sql/operators/sql.py", line 144, in _hook
    hook = conn.get_hook(hook_params=self.hook_params)
  File "/Users/sriharshabasiri/Library/Python/3.9/lib/python/site-packages/airflow/models/connection.py", line 359, in get_hook
    raise AirflowException(f'Unknown hook type "{self.conn_type}"')
airflow.exceptions.AirflowException: Unknown hook type "generic"
[2023-07-31T12:11:18.519-0700] {taskinstance.py:1345} INFO - Marking task as UP_FOR_RETRY. dag_id=testdag, task_id=task3_sql, execution_date=20230731T191111, start_date=20230731T191118, end_date=20230731T191118
[2023-07-31T12:11:18.522-0700] {standard_task_runner.py:104} ERROR - Failed to execute job 25 for task task3_sql (Unknown hook type "generic"; 63120)
[2023-07-31T12:11:18.569-0700] {local_task_job_runner.py:225} INFO - Task exited with return code 1
[2023-07-31T12:11:18.578-0700] {taskinstance.py:2653} INFO - 0 downstream tasks scheduled from follow-on schedule check
