[2023-07-31T12:00:17.825-0700] {taskinstance.py:1103} INFO - Dependencies all met for dep_context=non-requeueable deps ti=<TaskInstance: testdag.task3_sql manual__2023-07-31T18:59:10.610042+00:00 [queued]>
[2023-07-31T12:00:17.827-0700] {taskinstance.py:1103} INFO - Dependencies all met for dep_context=requeueable deps ti=<TaskInstance: testdag.task3_sql manual__2023-07-31T18:59:10.610042+00:00 [queued]>
[2023-07-31T12:00:17.827-0700] {taskinstance.py:1308} INFO - Starting attempt 2 of 2
[2023-07-31T12:00:17.832-0700] {taskinstance.py:1327} INFO - Executing <Task(SQLExecuteQueryOperator): task3_sql> on 2023-07-31 18:59:10.610042+00:00
[2023-07-31T12:00:17.834-0700] {standard_task_runner.py:57} INFO - Started process 61957 to run task
[2023-07-31T12:00:17.836-0700] {standard_task_runner.py:84} INFO - Running: ['airflow', 'tasks', 'run', 'testdag', 'task3_sql', 'manual__2023-07-31T18:59:10.610042+00:00', '--job-id', '14', '--raw', '--subdir', 'DAGS_FOLDER/testdag.py', '--cfg-path', '/var/folders/wq/wb1f6jvn7hs9kt8fvl1pjjf80000gn/T/tmpmnnxbnj5']
[2023-07-31T12:00:17.837-0700] {standard_task_runner.py:85} INFO - Job 14: Subtask task3_sql
[2023-07-31T12:00:17.852-0700] {task_command.py:410} INFO - Running <TaskInstance: testdag.task3_sql manual__2023-07-31T18:59:10.610042+00:00 [running]> on host sriharshas-macbook-pro.local
[2023-07-31T12:00:17.882-0700] {taskinstance.py:1545} INFO - Exporting env vars: AIRFLOW_CTX_DAG_OWNER='airflow' AIRFLOW_CTX_DAG_ID='testdag' AIRFLOW_CTX_TASK_ID='task3_sql' AIRFLOW_CTX_EXECUTION_DATE='2023-07-31T18:59:10.610042+00:00' AIRFLOW_CTX_TRY_NUMBER='2' AIRFLOW_CTX_DAG_RUN_ID='manual__2023-07-31T18:59:10.610042+00:00'
[2023-07-31T12:00:17.883-0700] {sql.py:265} INFO - Executing: SELECT 1; SELECT * FROM public.product LIMIT 1;
[2023-07-31T12:00:17.886-0700] {taskinstance.py:1824} ERROR - Task failed with exception
Traceback (most recent call last):
  File "/Users/sriharshabasiri/Library/Python/3.9/lib/python/site-packages/airflow/providers/common/sql/operators/sql.py", line 266, in execute
    hook = self.get_db_hook()
  File "/Users/sriharshabasiri/Library/Python/3.9/lib/python/site-packages/airflow/providers/common/sql/operators/sql.py", line 181, in get_db_hook
    return self._hook
  File "/Library/Developer/CommandLineTools/Library/Frameworks/Python3.framework/Versions/3.9/lib/python3.9/functools.py", line 969, in __get__
    val = self.func(instance)
  File "/Users/sriharshabasiri/Library/Python/3.9/lib/python/site-packages/airflow/providers/common/sql/operators/sql.py", line 143, in _hook
    conn = BaseHook.get_connection(self.conn_id)
  File "/Users/sriharshabasiri/Library/Python/3.9/lib/python/site-packages/airflow/hooks/base.py", line 72, in get_connection
    conn = Connection.get_connection_from_secrets(conn_id)
  File "/Users/sriharshabasiri/Library/Python/3.9/lib/python/site-packages/airflow/models/connection.py", line 463, in get_connection_from_secrets
    raise AirflowNotFoundException(f"The conn_id `{conn_id}` isn't defined")
airflow.exceptions.AirflowNotFoundException: The conn_id `sriharshabasiri` isn't defined
[2023-07-31T12:00:17.897-0700] {taskinstance.py:1345} INFO - Marking task as FAILED. dag_id=testdag, task_id=task3_sql, execution_date=20230731T185910, start_date=20230731T190017, end_date=20230731T190017
[2023-07-31T12:00:17.901-0700] {standard_task_runner.py:104} ERROR - Failed to execute job 14 for task task3_sql (The conn_id `sriharshabasiri` isn't defined; 61957)
[2023-07-31T12:00:17.941-0700] {local_task_job_runner.py:225} INFO - Task exited with return code 1
[2023-07-31T12:00:17.950-0700] {taskinstance.py:2653} INFO - 0 downstream tasks scheduled from follow-on schedule check
